[2022-03-20 20:19:26,822] {taskinstance.py:851} INFO - Dependencies all met for <TaskInstance: test_postgress.create_pet_table 2022-03-20T20:14:23.908169+00:00 [queued]>
[2022-03-20 20:19:26,839] {taskinstance.py:851} INFO - Dependencies all met for <TaskInstance: test_postgress.create_pet_table 2022-03-20T20:14:23.908169+00:00 [queued]>
[2022-03-20 20:19:26,839] {taskinstance.py:1042} INFO - 
--------------------------------------------------------------------------------
[2022-03-20 20:19:26,839] {taskinstance.py:1043} INFO - Starting attempt 2 of 2
[2022-03-20 20:19:26,839] {taskinstance.py:1044} INFO - 
--------------------------------------------------------------------------------
[2022-03-20 20:19:26,849] {taskinstance.py:1063} INFO - Executing <Task(PostgresOperator): create_pet_table> on 2022-03-20T20:14:23.908169+00:00
[2022-03-20 20:19:26,852] {standard_task_runner.py:52} INFO - Started process 50 to run task
[2022-03-20 20:19:26,856] {standard_task_runner.py:76} INFO - Running: ['airflow', 'tasks', 'run', 'test_postgress', 'create_pet_table', '2022-03-20T20:14:23.908169+00:00', '--job-id', '113', '--pool', 'default_pool', '--raw', '--subdir', 'DAGS_FOLDER/test_postgress.py', '--cfg-path', '/tmp/tmppg7ms9q4', '--error-file', '/tmp/tmp6_1q5wbg']
[2022-03-20 20:19:26,857] {standard_task_runner.py:77} INFO - Job 113: Subtask create_pet_table
[2022-03-20 20:19:26,900] {logging_mixin.py:104} INFO - Running <TaskInstance: test_postgress.create_pet_table 2022-03-20T20:14:23.908169+00:00 [running]> on host e39215f0be5b
[2022-03-20 20:19:26,940] {taskinstance.py:1257} INFO - Exporting the following env vars:
AIRFLOW_CTX_DAG_OWNER=airflow
AIRFLOW_CTX_DAG_ID=test_postgress
AIRFLOW_CTX_TASK_ID=create_pet_table
AIRFLOW_CTX_EXECUTION_DATE=2022-03-20T20:14:23.908169+00:00
AIRFLOW_CTX_DAG_RUN_ID=manual__2022-03-20T20:14:23.908169+00:00
[2022-03-20 20:19:26,940] {postgres.py:69} INFO - Executing: 
            insert into NEWS.NEWS_COMPANY(COMPANY)
            values ('asd')
          
[2022-03-20 20:19:26,949] {base.py:74} INFO - Using connection to: id: news_in. Host: ariflow, Port: 5432, Schema: news, Login: ariflow, Password: XXXXXXXX, extra: None
[2022-03-20 20:19:36,953] {taskinstance.py:1455} ERROR - could not translate host name "ariflow" to address: Temporary failure in name resolution
Traceback (most recent call last):
  File "/home/airflow/.local/lib/python3.6/site-packages/airflow/models/taskinstance.py", line 1112, in _run_raw_task
    self._prepare_and_execute_task_with_callbacks(context, task)
  File "/home/airflow/.local/lib/python3.6/site-packages/airflow/models/taskinstance.py", line 1285, in _prepare_and_execute_task_with_callbacks
    result = self._execute_task(context, task_copy)
  File "/home/airflow/.local/lib/python3.6/site-packages/airflow/models/taskinstance.py", line 1315, in _execute_task
    result = task_copy.execute(context=context)
  File "/home/airflow/.local/lib/python3.6/site-packages/airflow/providers/postgres/operators/postgres.py", line 71, in execute
    self.hook.run(self.sql, self.autocommit, parameters=self.parameters)
  File "/home/airflow/.local/lib/python3.6/site-packages/airflow/hooks/dbapi.py", line 173, in run
    with closing(self.get_conn()) as conn:
  File "/home/airflow/.local/lib/python3.6/site-packages/airflow/providers/postgres/hooks/postgres.py", line 108, in get_conn
    self.conn = psycopg2.connect(**conn_args)
  File "/home/airflow/.local/lib/python3.6/site-packages/psycopg2/__init__.py", line 127, in connect
    conn = _connect(dsn, connection_factory=connection_factory, **kwasync)
psycopg2.OperationalError: could not translate host name "ariflow" to address: Temporary failure in name resolution

[2022-03-20 20:19:36,958] {taskinstance.py:1503} INFO - Marking task as FAILED. dag_id=test_postgress, task_id=create_pet_table, execution_date=20220320T201423, start_date=20220320T201926, end_date=20220320T201936
[2022-03-20 20:19:36,981] {local_task_job.py:146} INFO - Task exited with return code 1
