[2022-03-20 21:29:26,110] {taskinstance.py:851} INFO - Dependencies all met for <TaskInstance: fetch_news.prepare_insert 2022-03-04T00:00:00+00:00 [queued]>
[2022-03-20 21:29:26,126] {taskinstance.py:851} INFO - Dependencies all met for <TaskInstance: fetch_news.prepare_insert 2022-03-04T00:00:00+00:00 [queued]>
[2022-03-20 21:29:26,126] {taskinstance.py:1042} INFO - 
--------------------------------------------------------------------------------
[2022-03-20 21:29:26,126] {taskinstance.py:1043} INFO - Starting attempt 7 of 7
[2022-03-20 21:29:26,126] {taskinstance.py:1044} INFO - 
--------------------------------------------------------------------------------
[2022-03-20 21:29:26,148] {taskinstance.py:1063} INFO - Executing <Task(PythonOperator): prepare_insert> on 2022-03-04T00:00:00+00:00
[2022-03-20 21:29:26,153] {standard_task_runner.py:52} INFO - Started process 1080 to run task
[2022-03-20 21:29:26,166] {standard_task_runner.py:76} INFO - Running: ['airflow', 'tasks', 'run', 'fetch_news', 'prepare_insert', '2022-03-04T00:00:00+00:00', '--job-id', '479', '--pool', 'default_pool', '--raw', '--subdir', 'DAGS_FOLDER/fetch_news.py', '--cfg-path', '/tmp/tmpp9x7koon', '--error-file', '/tmp/tmpg32qkl2f']
[2022-03-20 21:29:26,173] {standard_task_runner.py:77} INFO - Job 479: Subtask prepare_insert
[2022-03-20 21:29:26,312] {logging_mixin.py:104} INFO - Running <TaskInstance: fetch_news.prepare_insert 2022-03-04T00:00:00+00:00 [running]> on host e39215f0be5b
[2022-03-20 21:29:26,453] {taskinstance.py:1257} INFO - Exporting the following env vars:
AIRFLOW_CTX_DAG_OWNER=airflow
AIRFLOW_CTX_DAG_ID=fetch_news
AIRFLOW_CTX_TASK_ID=prepare_insert
AIRFLOW_CTX_EXECUTION_DATE=2022-03-04T00:00:00+00:00
AIRFLOW_CTX_DAG_RUN_ID=scheduled__2022-03-04T00:00:00+00:00
[2022-03-20 21:29:26,454] {taskinstance.py:1455} ERROR - 'articles'
Traceback (most recent call last):
  File "/home/airflow/.local/lib/python3.6/site-packages/airflow/models/taskinstance.py", line 1112, in _run_raw_task
    self._prepare_and_execute_task_with_callbacks(context, task)
  File "/home/airflow/.local/lib/python3.6/site-packages/airflow/models/taskinstance.py", line 1285, in _prepare_and_execute_task_with_callbacks
    result = self._execute_task(context, task_copy)
  File "/home/airflow/.local/lib/python3.6/site-packages/airflow/models/taskinstance.py", line 1315, in _execute_task
    result = task_copy.execute(context=context)
  File "/home/airflow/.local/lib/python3.6/site-packages/airflow/operators/python.py", line 117, in execute
    return_value = self.execute_callable()
  File "/home/airflow/.local/lib/python3.6/site-packages/airflow/operators/python.py", line 128, in execute_callable
    return self.python_callable(*self.op_args, **self.op_kwargs)
  File "/opt/airflow/dags/fetch_news.py", line 38, in _prepare_insert
    for art in data['articles']:
KeyError: 'articles'
[2022-03-20 21:29:26,456] {taskinstance.py:1503} INFO - Marking task as FAILED. dag_id=fetch_news, task_id=prepare_insert, execution_date=20220304T000000, start_date=20220320T212926, end_date=20220320T212926
[2022-03-20 21:29:26,537] {local_task_job.py:146} INFO - Task exited with return code 1
