[2022-03-21 10:03:06,169] {taskinstance.py:851} INFO - Dependencies all met for <TaskInstance: fetch_news.prepare_insert 2022-03-20T00:00:00+00:00 [queued]>
[2022-03-21 10:03:06,181] {taskinstance.py:851} INFO - Dependencies all met for <TaskInstance: fetch_news.prepare_insert 2022-03-20T00:00:00+00:00 [queued]>
[2022-03-21 10:03:06,181] {taskinstance.py:1042} INFO - 
--------------------------------------------------------------------------------
[2022-03-21 10:03:06,181] {taskinstance.py:1043} INFO - Starting attempt 1 of 1
[2022-03-21 10:03:06,181] {taskinstance.py:1044} INFO - 
--------------------------------------------------------------------------------
[2022-03-21 10:03:06,196] {taskinstance.py:1063} INFO - Executing <Task(PythonOperator): prepare_insert> on 2022-03-20T00:00:00+00:00
[2022-03-21 10:03:06,199] {standard_task_runner.py:52} INFO - Started process 1181 to run task
[2022-03-21 10:03:06,204] {standard_task_runner.py:76} INFO - Running: ['airflow', 'tasks', 'run', 'fetch_news', 'prepare_insert', '2022-03-20T00:00:00+00:00', '--job-id', '516', '--pool', 'default_pool', '--raw', '--subdir', 'DAGS_FOLDER/fetch_news.py', '--cfg-path', '/tmp/tmp2hifjybj', '--error-file', '/tmp/tmpyxp405_l']
[2022-03-21 10:03:06,204] {standard_task_runner.py:77} INFO - Job 516: Subtask prepare_insert
[2022-03-21 10:03:06,253] {logging_mixin.py:104} INFO - Running <TaskInstance: fetch_news.prepare_insert 2022-03-20T00:00:00+00:00 [running]> on host e39215f0be5b
[2022-03-21 10:03:06,304] {taskinstance.py:1257} INFO - Exporting the following env vars:
AIRFLOW_CTX_DAG_OWNER=airflow
AIRFLOW_CTX_DAG_ID=fetch_news
AIRFLOW_CTX_TASK_ID=prepare_insert
AIRFLOW_CTX_EXECUTION_DATE=2022-03-20T00:00:00+00:00
AIRFLOW_CTX_DAG_RUN_ID=scheduled__2022-03-20T00:00:00+00:00
[2022-03-21 10:03:06,305] {taskinstance.py:1455} ERROR - [Errno 2] No such file or directory: '/tmp_2022-03-20_2022-03-21/news_nvidia.sql'
Traceback (most recent call last):
  File "/home/airflow/.local/lib/python3.6/site-packages/airflow/models/taskinstance.py", line 1112, in _run_raw_task
    self._prepare_and_execute_task_with_callbacks(context, task)
  File "/home/airflow/.local/lib/python3.6/site-packages/airflow/models/taskinstance.py", line 1285, in _prepare_and_execute_task_with_callbacks
    result = self._execute_task(context, task_copy)
  File "/home/airflow/.local/lib/python3.6/site-packages/airflow/models/taskinstance.py", line 1315, in _execute_task
    result = task_copy.execute(context=context)
  File "/home/airflow/.local/lib/python3.6/site-packages/airflow/operators/python.py", line 117, in execute
    return_value = self.execute_callable()
  File "/home/airflow/.local/lib/python3.6/site-packages/airflow/operators/python.py", line 128, in execute_callable
    return self.python_callable(*self.op_args, **self.op_kwargs)
  File "/opt/airflow/dags/fetch_news.py", line 50, in _prepare_insert
    with open(sql_insert_file, 'w') as f:
FileNotFoundError: [Errno 2] No such file or directory: '/tmp_2022-03-20_2022-03-21/news_nvidia.sql'
[2022-03-21 10:03:06,307] {taskinstance.py:1503} INFO - Marking task as FAILED. dag_id=fetch_news, task_id=prepare_insert, execution_date=20220320T000000, start_date=20220321T100306, end_date=20220321T100306
[2022-03-21 10:03:06,337] {local_task_job.py:146} INFO - Task exited with return code 1
