[2022-03-20 20:18:34,120] {taskinstance.py:845} INFO - Dependencies not met for <TaskInstance: test_postgress.create_pet_table 2022-03-20T20:07:29.366717+00:00 [failed]>, dependency 'Task Instance State' FAILED: Task is in the 'failed' state which is not a valid state for execution. The task must be cleared in order to be run.
[2022-03-20 20:18:34,146] {local_task_job.py:93} INFO - Task is not able to be run
[2022-03-20 20:25:33,616] {taskinstance.py:851} INFO - Dependencies all met for <TaskInstance: test_postgress.create_pet_table 2022-03-20T20:07:29.366717+00:00 [queued]>
[2022-03-20 20:25:33,662] {taskinstance.py:851} INFO - Dependencies all met for <TaskInstance: test_postgress.create_pet_table 2022-03-20T20:07:29.366717+00:00 [queued]>
[2022-03-20 20:25:33,663] {taskinstance.py:1042} INFO - 
--------------------------------------------------------------------------------
[2022-03-20 20:25:33,663] {taskinstance.py:1043} INFO - Starting attempt 3 of 3
[2022-03-20 20:25:33,663] {taskinstance.py:1044} INFO - 
--------------------------------------------------------------------------------
[2022-03-20 20:25:33,704] {taskinstance.py:1063} INFO - Executing <Task(PostgresOperator): create_pet_table> on 2022-03-20T20:07:29.366717+00:00
[2022-03-20 20:25:33,708] {standard_task_runner.py:52} INFO - Started process 87 to run task
[2022-03-20 20:25:33,794] {standard_task_runner.py:76} INFO - Running: ['airflow', 'tasks', 'run', 'test_postgress', 'create_pet_table', '2022-03-20T20:07:29.366717+00:00', '--job-id', '126', '--pool', 'default_pool', '--raw', '--subdir', 'DAGS_FOLDER/test_postgress.py', '--cfg-path', '/tmp/tmpri073cw1', '--error-file', '/tmp/tmprz0n131v']
[2022-03-20 20:25:33,800] {standard_task_runner.py:77} INFO - Job 126: Subtask create_pet_table
[2022-03-20 20:25:33,945] {logging_mixin.py:104} INFO - Running <TaskInstance: test_postgress.create_pet_table 2022-03-20T20:07:29.366717+00:00 [running]> on host e39215f0be5b
[2022-03-20 20:25:34,141] {taskinstance.py:1257} INFO - Exporting the following env vars:
AIRFLOW_CTX_DAG_OWNER=airflow
AIRFLOW_CTX_DAG_ID=test_postgress
AIRFLOW_CTX_TASK_ID=create_pet_table
AIRFLOW_CTX_EXECUTION_DATE=2022-03-20T20:07:29.366717+00:00
AIRFLOW_CTX_DAG_RUN_ID=manual__2022-03-20T20:07:29.366717+00:00
[2022-03-20 20:25:34,141] {postgres.py:69} INFO - Executing: 
            insert into NEWS.NEWS_COMPANY(COMPANY)
            values ('asd')
          
[2022-03-20 20:25:34,164] {base.py:74} INFO - Using connection to: id: news_in. Host: postgres, Port: 5432, Schema: , Login: ariflow, Password: XXXXXXXX, extra: None
[2022-03-20 20:25:34,174] {taskinstance.py:1455} ERROR - FATAL:  password authentication failed for user "ariflow"
Traceback (most recent call last):
  File "/home/airflow/.local/lib/python3.6/site-packages/airflow/models/taskinstance.py", line 1112, in _run_raw_task
    self._prepare_and_execute_task_with_callbacks(context, task)
  File "/home/airflow/.local/lib/python3.6/site-packages/airflow/models/taskinstance.py", line 1285, in _prepare_and_execute_task_with_callbacks
    result = self._execute_task(context, task_copy)
  File "/home/airflow/.local/lib/python3.6/site-packages/airflow/models/taskinstance.py", line 1315, in _execute_task
    result = task_copy.execute(context=context)
  File "/home/airflow/.local/lib/python3.6/site-packages/airflow/providers/postgres/operators/postgres.py", line 71, in execute
    self.hook.run(self.sql, self.autocommit, parameters=self.parameters)
  File "/home/airflow/.local/lib/python3.6/site-packages/airflow/hooks/dbapi.py", line 173, in run
    with closing(self.get_conn()) as conn:
  File "/home/airflow/.local/lib/python3.6/site-packages/airflow/providers/postgres/hooks/postgres.py", line 108, in get_conn
    self.conn = psycopg2.connect(**conn_args)
  File "/home/airflow/.local/lib/python3.6/site-packages/psycopg2/__init__.py", line 127, in connect
    conn = _connect(dsn, connection_factory=connection_factory, **kwasync)
psycopg2.OperationalError: FATAL:  password authentication failed for user "ariflow"

[2022-03-20 20:25:34,176] {taskinstance.py:1503} INFO - Marking task as FAILED. dag_id=test_postgress, task_id=create_pet_table, execution_date=20220320T200729, start_date=20220320T202533, end_date=20220320T202534
[2022-03-20 20:25:34,260] {local_task_job.py:146} INFO - Task exited with return code 1
